Workbook

Sheet Summary
A1: BDO Shopmore Mastercard (PHP) - Statement Compilation
A2: Card ending 5660. Figures marked blue are typed from the statements; black are formulas over the Transactions sheet.
B4: Aug 25, 2026 | C4: Sep 24, 2026
A5: Statement date | B5: Aug 25, 2026 | C5: Sep 24, 2026
A6: Payment due date | B6: Sep 21, 2026 | C6: Oct 19, 2026
A7: Credit limit | B7: 425000 | C7: 720000
A8: Interest rate per month | B8: 0.03 | C8: 0.03
A9: Minimum amount due | B9: 850 | C9: 2785.37
A10: Total amount due (per statement) | B10: 27977.46 | C10: 92845.7
A11: Previous balance | B11: 22629.91 | C11: 27977.46
A12: Purchases and advances (per statement) | B12: 29470.64 | C12: 119094.74
A13: Fees/other debits (per statement) | B13: 1800 | C13: 0
A14: Finance + late charges (per statement) | B14: 0 | C14: 0
A15: Payments/other credits (per statement) | B15: -25923.09 | C15: -54226.5
A17: Reconciliation (formulas)
A18: Computed total (prev bal + all transactions) | B18: =B11+SUMIFS(Transactions!$G$2:$G$136,Transactions!$A$2:$A$136,B$4) | C18: =C11+SUMIFS(Transactions!$G$2:$G$136,Transactions!$A$2:$A$136,C$4)
A19: Difference vs statement total | B19: =ROUND(B18-B10,2) | C19: =ROUND(C18-C10,2)
A20: Sum of payments in transactions | B20: =SUMIFS(Transactions!$G$2:$G$136,Transactions!$A$2:$A$136,B$4,Transactions!$E$2:$E$136,"Payment") | C20: =SUMIFS(Transactions!$G$2:$G$136,Transactions!$A$2:$A$136,C$4,Transactions!$E$2:$E$136,"Payment")
A21: Sum of refunds/credits in transactions | B21: =SUMIFS(Transactions!$G$2:$G$136,Transactions!$A$2:$A$136,B$4,Transactions!$E$2:$E$136,"Refund/Credit") | C21: =SUMIFS(Transactions!$G$2:$G$136,Transactions!$A$2:$A$136,C$4,Transactions!$E$2:$E$136,"Refund/Credit")
A22: Statement payments/credits vs transactions (diff) | B22: =ROUND(B15-B20-B21,2) | C22: =ROUND(C15-C20-C21,2)
A23: Unpaid balance if only minimum paid | B23: =B10-B9 | C23: =C10-C9
A24: Next-month interest at 3% if minimum only | B24: =ROUND(B23*B8,2) | C24: =ROUND(C23*C8,2)
A25: Utilization (total due / credit limit) | B25: =B10/B7 | C25: =C10/C7
A27: Note: transcribed by hand from phone screenshots; the Difference row confirms each statement ties out to the printed total. Aug statement page 1 post dates for a few items were hard to read.

Sheet Transactions
A1: Statement | B1: Sale Date | C1: Post Date | D1: Merchant | E1: Category | F1: Reference | G1: Amount (PHP)
A2: Aug 25, 2026 | B2: 46259 | C2: 46259 | D2: ANNUAL MEMBERSHIP FEE | E2: Fees | G2: 1800
A3: Aug 25, 2026 | B3: 46228 | C3: 46230 | D3: SHOPEE PH MANDALUYONG PHL | E3: Shopee | G3: 288
A4: Aug 25, 2026 | B4: 46229 | C4: 46230 | D4: TIKTOK SHOP SELLER TAGUIG PHL | E4: Refund/Credit | G4: -50.6
A5: Aug 25, 2026 | B5: 46229 | C5: 46230 | D5: TIKTOK SHOP SELLER TAGUIG PHL | E5: Refund/Credit | G5: -48.58
A6: Aug 25, 2026 | B6: 46233 | C6: 46233 | D6: SAVEMORE SAN PEDRO LAGUNA PH | E6: Food/Grocery | G6: 546.1
A7: Aug 25, 2026 | B7: 46234 | C7: 46236 | D7: GRAB PASIG CITY PHL | E7: Transport | G7: 20
A8: Aug 25, 2026 | B8: 46234 | C8: 46236 | D8: GRAB PASIG CITY PHL | E8: Transport | G8: 18.06
A9: Aug 25, 2026 | B9: 46234 | C9: 46236 | D9: GRAB MAKATI PHL | E9: Transport | G9: 1157
A10: Aug 25, 2026 | B10: 46235 | C10: 46236 | D10: PIZZA HUT CLTX SAN PED SAN PEDRO PHL | E10: Food/Grocery | G10: 403.39
A11: Aug 25, 2026 | B11: 46235 | C11: 46238 | D11: SUPER 8 SAN PEDRO LAGUNA SAN PE PHL | E11: Food/Grocery | G11: 115
A12: Aug 25, 2026 | B12: 46235 | C12: 46251 | D12: PLDT AUTOCHARGE MAKATI CITY PH | E12: Utilities/Bills | F12: 0376499375 | G12: 1699.01
A13: Aug 25, 2026 | B13: 46237 | C13: 46239 | D13: SHOPEE PH MANDALUYONG PHL | E13: Shopee | G13: 204
A14: Aug 25, 2026 | B14: 46238 | C14: 46240 | D14: SHOPEE PH MANDALUYONG PHL | E14: Shopee | G14: 409
A15: Aug 25, 2026 | B15: 46238 | C15: 46240 | D15: SHOPEE PH MANDALUYONG PHL | E15: Shopee | G15: 216
A16: Aug 25, 2026 | B16: 46240 | C16: 46243 | D16: TIKTOK SHOP SELLER TAGUIG PHL | E16: TikTok Shop | G16: 1038.18
A17: Aug 25, 2026 | B17: 46242 | C17: 46244 | D17: SHOPEE PH MANDALUYONG PHL | E17: Shopee | G17: 23
A18: Aug 25, 2026 | B18: 46244 | C18: 46244 | D18: H&M TAGUIG PH | E18: Shopping (retail) | G18: 848.3
A19: Aug 25, 2026 | B19: 46244 | C19: 46245 | D19: 484 SM AURA TAGUIG PHL | E19: Shopping (retail) | G19: 79
A20: Aug 25, 2026 | B20: 46245 | C20: 46247 | D20: SHOPEE PH MANDALUYONG PHL | E20: Shopee | G20: 502
A21: Aug 25, 2026 | B21: 46247 | C21: 46250 | D21: SHOPEE PH MANDALUYONG PHL | E21: Shopee | G21: 8568
A22: Aug 25, 2026 | B22: 46249 | C22: 46251 | D22: SHOPEE PH MANDALUYONG PHL | E22: Shopee | G22: 3115
A23: Aug 25, 2026 | B23: 46250 | C23: 46252 | D23: SHOPEE PH MANDALUYONG PHL | E23: Shopee | G23: 1234
A24: Aug 25, 2026 | B24: 46251 | C24: 46252 | D24: MERALCO AUTOCHARGE PASIG CITY PH | E24: Utilities/Bills | F24: 1248117325 | G24: 1317.28
A25: Aug 25, 2026 | B25: 46251 | C25: 46253 | D25: SHOPEE PH MANDALUYONG PHL | E25: Shopee | G25: 224
A26: Aug 25, 2026 | B26: 46252 | C26: 46253 | D26: SHOPEE PH MANDALUYONG PHL | E26: Refund/Credit | G26: -1960
A27: Aug 25, 2026 | B27: 46253 | C27: 46253 | D27: LAZADA PH TAGUIG PH | E27: Lazada | F27: 20260819901800021517156 | G27: 1097.3
A28: Aug 25, 2026 | B28: 46253 | C28: 46253 | D28: PAYMENT RECEIVED - THANK YOU | E28: Payment | G28: -22629.91
A29: Aug 25, 2026 | B29: 46253 | C29: 46257 | D29: SHOPEE PH MANDALUYONG PHL | E29: Shopee | G29: 98
A30: Aug 25, 2026 | B30: 46254 | C30: 46254 | D30: LAZADA PH TAGUIG PH | E30: Lazada | F30: 20260819901800021524370 | G30: 1130
A31: Aug 25, 2026 | B31: 46254 | C31: 46257 | D31: SHOPEE PH MANDALUYONG PHL | E31: Refund/Credit | G31: -1234
A32: Aug 25, 2026 | B32: 46256 | C32: 46257 | D32: LAZADA PH TAGUIG PH | E32: Lazada | F32: 20260822908400021915909 | G32: 1150.02
A33: Aug 25, 2026 | B33: 46256 | C33: 46258 | D33: SHOPEE PH MANDALUYONG PHL | E33: Shopee | G33: 532
A34: Aug 25, 2026 | B34: 46256 | C34: 46258 | D34: SHOPEE PH MANDALUYONG PHL | E34: Shopee | G34: 1090
A35: Aug 25, 2026 | B35: 46256 | C35: 46258 | D35: SHOPEE PH MANDALUYONG PHL | E35: Shopee | G35: 406
A36: Aug 25, 2026 | B36: 46256 | C36: 46258 | D36: SHOPEE PH MANDALUYONG PHL | E36: Shopee | G36: 68
A37: Aug 25, 2026 | B37: 46257 | C37: 46259 | D37: SHOPEE PH MANDALUYONG PHL | E37: Shopee | G37: 356
A38: Aug 25, 2026 | B38: 46257 | C38: 46259 | D38: SHOPEE PH MANDALUYONG PHL | E38: Shopee | G38: 483
A39: Aug 25, 2026 | B39: 46257 | C39: 46259 | D39: SHOPEE PH MANDALUYONG PHL | E39: Shopee | G39: 381
A40: Aug 25, 2026 | B40: 46257 | C40: 46259 | D40: SHOPEE PH MANDALUYONG PHL | E40: Shopee | G40: 406
...

Sheet By Category
A1: Category | B1: Aug 25, 2026 | C1: Sep 24, 2026 | D1: Total | E1: # Txns
A2: Fees | B2: =SUMIFS(Transactions!$G$2:$G$136,Transactions!$A$2:$A$136,"Aug 25, 2026",Transactions!$E$2:$E$136,$A2) | C2: =SUMIFS(Transactions!$G$2:$G$136,Transactions!$A$2:$A$136,"Sep 24, 2026",Transactions!$E$2:$E$136,$A2) | D2: =B2+C2 | E2: =COUNTIFS(Transactions!$E$2:$E$136,$A2)
A3: Food/Grocery | B3: =SUMIFS(Transactions!$G$2:$G$136,Transactions!$A$2:$A$136,"Aug 25, 2026",Transactions!$E$2:$E$136,$A3) | C3: =SUMIFS(Transactions!$G$2:$G$136,Transactions!$A$2:$A$136,"Sep 24, 2026",Transactions!$E$2:$E$136,$A3) | D3: =B3+C3 | E3: =COUNTIFS(Transactions!$E$2:$E$136,$A3)
A4: Gym | B4: =SUMIFS(Transactions!$G$2:$G$136,Transactions!$A$2:$A$136,"Aug 25, 2026",Transactions!$E$2:$E$136,$A4) | C4: =SUMIFS(Transactions!$G$2:$G$136,Transactions!$A$2:$A$136,"Sep 24, 2026",Transactions!$E$2:$E$136,$A4) | D4: =B4+C4 | E4: =COUNTIFS(Transactions!$E$2:$E$136,$A4)
A5: Lazada | B5: =SUMIFS(Transactions!$G$2:$G$136,Transactions!$A$2:$A$136,"Aug 25, 2026",Transactions!$E$2:$E$136,$A5) | C5: =SUMIFS(Transactions!$G$2:$G$136,Transactions!$A$2:$A$136,"Sep 24, 2026",Transactions!$E$2:$E$136,$A5) | D5: =B5+C5 | E5: =COUNTIFS(Transactions!$E$2:$E$136,$A5)
A6: Shopee | B6: =SUMIFS(Transactions!$G$2:$G$136,Transactions!$A$2:$A$136,"Aug 25, 2026",Transactions!$E$2:$E$136,$A6) | C6: =SUMIFS(Transactions!$G$2:$G$136,Transactions!$A$2:$A$136,"Sep 24, 2026",Transactions!$E$2:$E$136,$A6) | D6: =B6+C6 | E6: =COUNTIFS(Transactions!$E$2:$E$136,$A6)
A7: Shopping (retail) | B7: =SUMIFS(Transactions!$G$2:$G$136,Transactions!$A$2:$A$136,"Aug 25, 2026",Transactions!$E$2:$E$136,$A7) | C7: =SUMIFS(Transactions!$G$2:$G$136,Transactions!$A$2:$A$136,"Sep 24, 2026",Transactions!$E$2:$E$136,$A7) | D7: =B7+C7 | E7: =COUNTIFS(Transactions!$E$2:$E$136,$A7)
A8: TikTok Shop | B8: =SUMIFS(Transactions!$G$2:$G$136,Transactions!$A$2:$A$136,"Aug 25, 2026",Transactions!$E$2:$E$136,$A8) | C8: =SUMIFS(Transactions!$G$2:$G$136,Transactions!$A$2:$A$136,"Sep 24, 2026",Transactions!$E$2:$E$136,$A8) | D8: =B8+C8 | E8: =COUNTIFS(Transactions!$E$2:$E$136,$A8)
A9: Transport | B9: =SUMIFS(Transactions!$G$2:$G$136,Transactions!$A$2:$A$136,"Aug 25, 2026",Transactions!$E$2:$E$136,$A9) | C9: =SUMIFS(Transactions!$G$2:$G$136,Transactions!$A$2:$A$136,"Sep 24, 2026",Transactions!$E$2:$E$136,$A9) | D9: =B9+C9 | E9: =COUNTIFS(Transactions!$E$2:$E$136,$A9)
A10: Utilities/Bills | B10: =SUMIFS(Transactions!$G$2:$G$136,Transactions!$A$2:$A$136,"Aug 25, 2026",Transactions!$E$2:$E$136,$A10) | C10: =SUMIFS(Transactions!$G$2:$G$136,Transactions!$A$2:$A$136,"Sep 24, 2026",Transactions!$E$2:$E$136,$A10) | D10: =B10+C10 | E10: =COUNTIFS(Transactions!$E$2:$E$136,$A10)
A11: Refund/Credit | B11: =SUMIFS(Transactions!$G$2:$G$136,Transactions!$A$2:$A$136,"Aug 25, 2026",Transactions!$E$2:$E$136,$A11) | C11: =SUMIFS(Transactions!$G$2:$G$136,Transactions!$A$2:$A$136,"Sep 24, 2026",Transactions!$E$2:$E$136,$A11) | D11: =B11+C11 | E11: =COUNTIFS(Transactions!$E$2:$E$136,$A11)
A12: Net (excl. payments) | B12: =SUM(B2:B11) | C12: =SUM(C2:C11) | D12: =SUM(D2:D11) | E12: =SUM(E2:E11)

Sheet By Merchant
A1: Merchant | B1: Aug 25, 2026 | C1: Sep 24, 2026 | D1: Total
A2: 484 SM AURA TAGUIG PHL | B2: =SUMIFS(Transactions!$G$2:$G$136,Transactions!$A$2:$A$136,"Aug 25, 2026",Transactions!$D$2:$D$136,$A2) | C2: =SUMIFS(Transactions!$G$2:$G$136,Transactions!$A$2:$A$136,"Sep 24, 2026",Transactions!$D$2:$D$136,$A2) | D2: =B2+C2
A3: ANNUAL MEMBERSHIP FEE | B3: =SUMIFS(Transactions!$G$2:$G$136,Transactions!$A$2:$A$136,"Aug 25, 2026",Transactions!$D$2:$D$136,$A3) | C3: =SUMIFS(Transactions!$G$2:$G$136,Transactions!$A$2:$A$136,"Sep 24, 2026",Transactions!$D$2:$D$136,$A3) | D3: =B3+C3
A4: BAYAD CENTER MERALCO PASIG PHL | B4: =SUMIFS(Transactions!$G$2:$G$136,Transactions!$A$2:$A$136,"Aug 25, 2026",Transactions!$D$2:$D$136,$A4) | C4: =SUMIFS(Transactions!$G$2:$G$136,Transactions!$A$2:$A$136,"Sep 24, 2026",Transactions!$D$2:$D$136,$A4) | D4: =B4+C4
A5: GRAB MAKATI PHL | B5: =SUMIFS(Transactions!$G$2:$G$136,Transactions!$A$2:$A$136,"Aug 25, 2026",Transactions!$D$2:$D$136,$A5) | C5: =SUMIFS(Transactions!$G$2:$G$136,Transactions!$A$2:$A$136,"Sep 24, 2026",Transactions!$D$2:$D$136,$A5) | D5: =B5+C5
A6: GRAB PASIG CITY PHL | B6: =SUMIFS(Transactions!$G$2:$G$136,Transactions!$A$2:$A$136,"Aug 25, 2026",Transactions!$D$2:$D$136,$A6) | C6: =SUMIFS(Transactions!$G$2:$G$136,Transactions!$A$2:$A$136,"Sep 24, 2026",Transactions!$D$2:$D$136,$A6) | D6: =B6+C6
A7: H&M MUNTINLUPA PH | B7: =SUMIFS(Transactions!$G$2:$G$136,Transactions!$A$2:$A$136,"Aug 25, 2026",Transactions!$D$2:$D$136,$A7) | C7: =SUMIFS(Transactions!$G$2:$G$136,Transactions!$A$2:$A$136,"Sep 24, 2026",Transactions!$D$2:$D$136,$A7) | D7: =B7+C7
A8: H&M TAGUIG PH | B8: =SUMIFS(Transactions!$G$2:$G$136,Transactions!$A$2:$A$136,"Aug 25, 2026",Transactions!$D$2:$D$136,$A8) | C8: =SUMIFS(Transactions!$G$2:$G$136,Transactions!$A$2:$A$136,"Sep 24, 2026",Transactions!$D$2:$D$136,$A8) | D8: =B8+C8
A9: LANDMARK ALABANG DEPAR MUNTINLUPA PHL | B9: =SUMIFS(Transactions!$G$2:$G$136,Transactions!$A$2:$A$136,"Aug 25, 2026",Transactions!$D$2:$D$136,$A9) | C9: =SUMIFS(Transactions!$G$2:$G$136,Transactions!$A$2:$A$136,"Sep 24, 2026",Transactions!$D$2:$D$136,$A9) | D9: =B9+C9
A10: LANDMARK ALABANG SUPER MUNTINLUPA PHL | B10: =SUMIFS(Transactions!$G$2:$G$136,Transactions!$A$2:$A$136,"Aug 25, 2026",Transactions!$D$2:$D$136,$A10) | C10: =SUMIFS(Transactions!$G$2:$G$136,Transactions!$A$2:$A$136,"Sep 24, 2026",Transactions!$D$2:$D$136,$A10) | D10: =B10+C10
A11: LAZADA PH TAGUIG PH | B11: =SUMIFS(Transactions!$G$2:$G$136,Transactions!$A$2:$A$136,"Aug 25, 2026",Transactions!$D$2:$D$136,$A11) | C11: =SUMIFS(Transactions!$G$2:$G$136,Transactions!$A$2:$A$136,"Sep 24, 2026",Transactions!$D$2:$D$136,$A11) | D11: =B11+C11
A12: MERALCO AUTOCHARGE PASIG CITY PH | B12: =SUMIFS(Transactions!$G$2:$G$136,Transactions!$A$2:$A$136,"Aug 25, 2026",Transactions!$D$2:$D$136,$A12) | C12: =SUMIFS(Transactions!$G$2:$G$136,Transactions!$A$2:$A$136,"Sep 24, 2026",Transactions!$D$2:$D$136,$A12) | D12: =B12+C12
A13: P AND L FITNESS GYM SAN PEDRO PHL | B13: =SUMIFS(Transactions!$G$2:$G$136,Transactions!$A$2:$A$136,"Aug 25, 2026",Transactions!$D$2:$D$136,$A13) | C13: =SUMIFS(Transactions!$G$2:$G$136,Transactions!$A$2:$A$136,"Sep 24, 2026",Transactions!$D$2:$D$136,$A13) | D13: =B13+C13
... A19: TIKTOK SHOP SELLER TAGUIG PHL | B19: =SUMIFS(Transactions!$G$2:$G$136,Transactions!$A$2:$A$136,"Aug 25, 2026",Transactions!$D$2:$D$136,$A19) | C19: =SUMIFS(Transactions!$G$2:$G$136,Transactions!$A$2:$A$136,"Sep 24, 2026",Transactions!$D$2:$D$136,$A19) | D19: =B19+C19
